Workbook

Sheet Trade Log
B2: The5ers | $2,500 High Stakes | Trade Tracker | H2: 2500
B4: Balance | C4: =H4 -> 2500 | D4: Today P&L | E4: =H7 -> 0 | F4: =H14 -> Step 1 | H4: =H2+IFERROR(SUM(E14:E10000),0) -> 2500
B5: Total P&L | C5: =H5 -> 0 | D5: Win Rate | E5: =H13 -> 0 | H5: =H4-H2 -> 0
B6: Daily Limit Left | C6: =H9 -> 125 | D6: DD Remaining | E6: =H11 -> 250 | H6: =IFERROR(H5/H2,0) -> 0
H7: =IFERROR(SUMIF(C14:C10000,TODAY(),E14:E10000),0) -> 0
B8: =IF(H15>=1,"✅ STEP 1 COMPLETE — Now in Step 2!","Step 1 — Profit Target: 8% ($200) "&REPT("█",MIN(ROUND(H15*20,0),20))&REPT("░",MAX(20-ROUND(H15*20,0),0))&" "&TEXT(MIN(H15,1),"0.0%")) -> Step 1 — Profit Target: 8% ($200) ░░░░░░░░░░░░░░░░░░░░ 0.0% | H8: =IFERROR(ABS(MIN(H7,0))/H2,0) -> 0
H9: =H2*0.05-ABS(MIN(H7,0)) -> 125
B10: =IF(H15<1,"⏳ Complete Step 1 first",IF(H16>=1,"🏆 STEP 2 COMPLETE — You're Funded!","Step 2 — Profit Target: 5% ($125) "&REPT("█",MIN(ROUND(H16*20,0),20))&REPT("░",MAX(20-ROUND(H16*20,0),0))&" "&TEXT(MIN(H16,1),"0.0%"))) -> ⏳ Complete Step 1 first | H10: =IFERROR(ABS(MIN(H5,0))/H2,0) -> 0
B11: 💡 Just type the day number (e.g. 11) in the Day column — the full date fills automatically | H11: =H2*0.1-ABS(MIN(H5,0)) -> 250
B12: =IF(H8>=0.05,"⚠️ DAILY LOSS LIMIT REACHED ($125) — STOP TRADING TODAY",IF(H8>=0.03,"⚠️ Caution: "&TEXT(H8,"0.0%")&" of daily limit used ($"&TEXT(ABS(MIN(H7,0)),"#,##0.00")&" / $125)","✅ Daily loss OK — "&TEXT(H9,"$#,##0.00")&" remaining today")) -> ✅ Daily loss OK — $125.00 remaining today | H12: =COUNTA(B14:B10000) -> 1
B13: Day | C13: Date | D13: R:R | E13: P&L ($) | F13: Balance ($) | G13: Notes | H13: =IFERROR(COUNTIF(E14:E10000,">0")/H12,0) -> 0
C14: =IF(B14="","",DATE(YEAR(TODAY()),MONTH(TODAY()),B14)) | E14: =IF(B14="","",H2+IFERROR(SUM($D$14:D14),0)) | F14: =IF(B14="","",H2+IFERROR(SUM($E$14:E14),0)) | H14: =IF(H15>=1,IF(H16>=1,"✅ FUNDED","Step 2"),"Step 1") -> Step 1
C15: =IF(B15="","",DATE(YEAR(TODAY()),MONTH(TODAY()),B15)) | E15: =IF(B15="","",H2+IFERROR(SUM($D$14:D15),0)) | F15: =IF(B15="","",H2+IFERROR(SUM($E$14:E15),0)) | H15: =IFERROR(MAX(H5,0)/(H2*0.08),0) -> 0
C16: =IF(B16="","",DATE(YEAR(TODAY()),MONTH(TODAY()),B16)) | E16: =IF(B16="","",H2+IFERROR(SUM($D$14:D16),0)) | F16: =IF(B16="","",H2+IFERROR(SUM($E$14:E16),0)) | H16: =IFERROR(IF(H15>=1,MAX(H5-H2*0.08,0)/(H2*0.05),0),0) -> 0
C17: =IF(B17="","",DATE(YEAR(TODAY()),MONTH(TODAY()),B17)) | E17: =IF(B17="","",H2+IFERROR(SUM($D$14:D17),0)) | F17: =IF(B17="","",H2+IFERROR(SUM($E$14:E17),0)) | H17: =IFERROR(COUNTIF(D14:D10000,">0")/H12,0) -> 0
C18: =IF(B18="","",DATE(YEAR(TODAY()),MONTH(TODAY()),B18)) | E18: =IF(B18="","",H2+IFERROR(SUM($D$14:D18),0)) | F18: =IF(B18="","",H2+IFERROR(SUM($E$14:E18),0))
C19: =IF(B19="","",DATE(YEAR(TODAY()),MONTH(TODAY()),B19)) | E19: =IF(B19="","",H2+IFERROR(SUM($D$14:D19),0)) | F19: =IF(B19="","",H2+IFERROR(SUM($E$14:E19),0))
C20: =IF(B20="","",DATE(YEAR(TODAY()),MONTH(TODAY()),B20)) | E20: =IF(B20="","",H2+IFERROR(SUM($D$14:D20),0)) | F20: =IF(B20="","",H2+IFERROR(SUM($E$14:E20),0))
C21: =IF(B21="","",DATE(YEAR(TODAY()),MONTH(TODAY()),B21)) | E21: =IF(B21="","",H2+IFERROR(SUM($D$14:D21),0)) | F21: =IF(B21="","",H2+IFERROR(SUM($E$14:E21),0))
C22: =IF(B22="","",DATE(YEAR(TODAY()),MONTH(TODAY()),B22)) | E22: =IF(B22="","",H2+IFERROR(SUM($D$14:D22),0)) | F22: =IF(B22="","",H2+IFERROR(SUM($E$14:E22),0))
C23: =IF(B23="","",DATE(YEAR(TODAY()),MONTH(TODAY()),B23)) | E23: =IF(B23="","",H2+IFERROR(SUM($D$14:D23),0)) | F23: =IF(B23="","",H2+IFERROR(SUM($E$14:E23),0))
C24: =IF(B24="","",DATE(YEAR(TODAY()),MONTH(TODAY()),B24)) | E24: =IF(B24="","",H2+IFERROR(SUM($D$14:D24),0)) | F24: =IF(B24="","",H2+IFERROR(SUM($E$14:E24),0))
C25: =IF(B25="","",DATE(YEAR(TODAY()),MONTH(TODAY()),B25)) | E25: =IF(B25="","",H2+IFERROR(SUM($D$14:D25),0)) | F25: =IF(B25="","",H2+IFERROR(SUM($E$14:E25),0))
C26: =IF(B26="","",DATE(YEAR(TODAY()),MONTH(TODAY()),B26)) | E26: =IF(B26="","",H2+IFERROR(SUM($D$14:D26),0)) | F26: =IF(B26="","",H2+IFERROR(SUM($E$14:E26),0))
C27: =IF(B27="","",DATE(YEAR(TODAY()),MONTH(TODAY()),B27)) | E27: =IF(B27="","",H2+IFERROR(SUM($D$14:D27),0)) | F27: =IF(B27="","",H2+IFERROR(SUM($E$14:E27),0))
C28: =IF(B28="","",DATE(YEAR(TODAY()),MONTH(TODAY()),B28)) | E28: =IF(B28="","",H2+IFERROR(SUM($D$14:D28),0)) | F28: =IF(B28="","",H2+IFERROR(SUM($E$14:E28),0))
C29: =IF(B29="","",DATE(YEAR(TODAY()),MONTH(TODAY()),B29)) | E29: =IF(B29="","",H2+IFERROR(SUM($D$14:D29),0)) | F29: =IF(B29="","",H2+IFERROR(SUM($E$14:E29),0))
C30: =IF(B30="","",DATE(YEAR(TODAY()),MONTH(TODAY()),B30)) | E30: =IF(B30="","",H2+IFERROR(SUM($D$14:D30),0)) | F30: =IF(B30="","",H2+IFERROR(SUM($E$14:E30),0))
C31: =IF(B31="","",DATE(YEAR(TODAY()),MONTH(TODAY()),B31)) | E31: =IF(B31="","",H2+IFERROR(SUM($D$14:D31),0)) | F31: =IF(B31="","",H2+IFERROR(SUM($E$14:E31),0))
C32: =IF(B32="","",DATE(YEAR(TODAY()),MONTH(TODAY()),B32)) | E32: =IF(B32="","",H2+IFERROR(SUM($D$14:D32),0)) | F32: =IF(B32="","",H2+IFERROR(SUM($E$14:E32),0))
C33: =IF(B33="","",DATE(YEAR(TODAY()),MONTH(TODAY()),B33)) | E33: =IF(B33="","",H2+IFERROR(SUM($D$14:D33),0)) | F33: =IF(B33="","",H2+IFERROR(SUM($E$14:E33),0))
C34: =IF(B34="","",DATE(YEAR(TODAY()),MONTH(TODAY()),B34)) | E34: =IF(B34="","",H2+IFERROR(SUM($D$14:D34),0)) | F34: =IF(B34="","",H2+IFERROR(SUM($E$14:E34),0))
C35: =IF(B35="","",DATE(YEAR(TODAY()),MONTH(TODAY()),B35)) | E35: =IF(B35="","",H2+IFERROR(SUM($D$14:D35),0)) | F35: =IF(B35="","",H2+IFERROR(SUM($E$14:E35),0))
C36: =IF(B36="","",DATE(YEAR(TODAY()),MONTH(TODAY()),B36)) | E36: =IF(B36="","",H2+IFERROR(SUM($D$14:D36),0)) | F36: =IF(B36="","",H2+IFERROR(SUM($E$14:E36),0))
C37: =IF(B37="","",DATE(YEAR(TODAY()),MONTH(TODAY()),B37)) | E37: =IF(B37="","",H2+IFERROR(SUM($D$14:D37),0)) | F37: =IF(B37="","",H2+IFERROR(SUM($E$14:E37),0))
C38: =IF(B38="","",DATE(YEAR(TODAY()),MONTH(TODAY()),B38)) | E38: =IF(B38="","",H2+IFERROR(SUM($D$14:D38),0)) | F38: =IF(B38="","",H2+IFERROR(SUM($E$14:E38),0))
C39: =IF(B39="","",DATE(YEAR(TODAY()),MONTH(TODAY()),B39)) | E39: =IF(B39="","",H2+IFERROR(SUM($D$14:D39),0)) | F39: =IF(B39="","",H2+IFERROR(SUM($E$14:E39),0))
C40: =IF(B40="","",DATE(YEAR(TODAY()),MONTH(TODAY()),B40)) | E40: =IF(B40="","",H2+IFERROR(SUM($D$14:D40),0)) | F40: =IF(B40="","",H2+IFERROR(SUM($E$14:E40),0))
C41: =IF(B41="","",DATE(YEAR(TODAY()),MONTH(TODAY()),B41)) | E41: =IF(B41="","",H2+IFERROR(SUM($D$14:D41),0)) | F41: =IF(B41="","",H2+IFERROR(SUM($E$14:E41),0))
C42: =IF(B42="","",DATE(YEAR(TODAY()),MONTH(TODAY()),B42)) | E42: =IF(B42="","",H2+IFERROR(SUM($D$14:D42),0)) | F42: =IF(B42="","",H2+IFERROR(SUM($E$14:E42),0))
...

Sheet Dashboard
B2: Account Dashboard — The5ers $2,500
B4: 📊 ACCOUNT SUMMARY
B6: Account Size | C6: ='Trade Log'!H2 -> 2500
B7: Current Balance | C7: ='Trade Log'!H4 -> 2500
B8: Total P&L ($) | C8: ='Trade Log'!H5 -> 0
B9: Total P&L (%) | C9: ='Trade Log'!H6 -> 0
B10: Current Phase | C10: ='Trade Log'!H14 -> Step 1
B12: ⚠️ RISK LIMITS
B14: Today's P&L | C14: ='Trade Log'!H7 -> 0
B15: Daily Loss Used | C15: ='Trade Log'!H8 -> 0
B16: Daily Limit Remaining | C16: ='Trade Log'!H9 -> 125
B17: Overall Drawdown | C17: ='Trade Log'!H10 -> 0
B18: DD Remaining | C18: ='Trade Log'!H11 -> 250
B20: 📈 PERFORMANCE
B22: Total Trades | C22: ='Trade Log'!H12 -> 1
B23: Win Rate | C23: ='Trade Log'!H13 -> 0
B25: 🎯 CHALLENGE PROGRESS
B27: Step 1 Progress (8%) | C27: ='Trade Log'!H15 -> 0
B28: Step 2 Progress (5%) | C28: ='Trade Log'!H16 -> 0
B30: 🚦 ALERTS
B32: Daily Loss | C32: =IF('Trade Log'!H8>=0.05,"🚨 STOP — Limit Hit",IF('Trade Log'!H8>=0.03,"⚠️ Caution","✅ OK")) -> ✅ OK
B33: Max Drawdown | C33: =IF('Trade Log'!H10>=0.1,"🚨 BLOWN — Max DD Hit","✅ OK") -> ✅ OK
B34: Step 1 | C34: =IF('Trade Log'!H15>=1,"🏆 PASSED!","⏳ In Progress") -> ⏳ In Progress
B35: Step 2 | C35: =IF('Trade Log'!H16>=1,"🏆 FUNDED!","⏳ In Progress") -> ⏳ In Progress
